<?xml version='1.0'?>

<robot name="custom_bot" xmlns:xacro="http://www.ros.org/wiki/xacro">

<!--> inculde gazebo file for sensors definitions_______________<!-->

  <xacro:include filename="$(find slam_project)/urdf/custom_bot.gazebo" />
  
  <link name="robot_footprint"></link>

  <joint name="robot_footprint_joint" type="fixed">
    <origin xyz="0 0 0" rpy="0 0 0" />
    <parent link="robot_footprint"/>
    <child link="chassis" />
  </joint>



<!--> chassis___________________________________________________<!-->


  <link name='chassis'>
    <pose>0 0 0.1 0 0 0</pose>

    <inertial>
      <mass value="15.0"/>
      <origin xyz="0.0 0 0" rpy=" 0 0 0"/>
      <inertia
          ixx="0.0" ixy="0" ixz="0"
          iyy="0.0" iyz="0"
          izz="0.0"
      />
    </inertial>

    <collision name='collision'>
      <origin xyz="0 0 0" rpy=" 0 0 0"/> 
      <geometry>
        <cylinder radius=".205" length="0.1"/>
      </geometry>
    </collision>

    <visual name='chassis_visual'>
      <origin xyz="0 0 0" rpy=" 0 0 0"/>
      <geometry>
        <cylinder radius=".205" length="0.1"/>
      </geometry>
    </visual>

    <visual name='chassis_visual2'>
      <origin xyz="0 0 0.05" rpy=" 0 0 0"/>
      <geometry>
        <sphere radius="0.1"/>
      </geometry>
    </visual>

    <visual name='chassis_visual3'>
      <origin xyz="0.15 0 0.05" rpy=" 0 0 0"/>
      <geometry>
        <cylinder radius="0.04" length="0.03"/>
      </geometry>
    </visual>

    <visual name='chassis_visual4'>
      <origin xyz="0.07 0 0.05" rpy=" 0 0 0"/>
      <geometry>
        <box size="0.16 0.08 0.03"/>
      </geometry>
    </visual>

 
    <collision name='back_caster_collision'>
      <origin xyz="-0.15 0 -0.05" rpy=" 0 0 0"/>
      <geometry>
        <sphere radius="0.0499"/>
      </geometry>
    </collision>

    <visual name='back_caster_visual'>
      <origin xyz="-0.15 0 -0.05" rpy=" 0 0 0"/>
      <geometry>
        <sphere radius="0.05"/>
      </geometry>
    </visual>

    <collision name='front_caster_collision'>
      <origin xyz="0.15 0 -0.05" rpy=" 0 0 0"/>
      <geometry>
        <sphere radius="0.0499"/>
      </geometry>
    </collision>

    <visual name='front_caster_visual'>
      <origin xyz="0.15 0 -0.05" rpy=" 0 0 0"/>
      <geometry>
        <sphere radius="0.05"/>
      </geometry>
    </visual>

  </link>

<!--> wheels_____________________________________________________<!-->

  <link name='left_wheel'>
    <inertial>
      <mass value="5.0"/>
      <origin xyz="0.0 0 0" rpy=" 0 1.5705 1.5707"/>
      <inertia
          ixx="0.0" ixy="0" ixz="0"
          iyy="0.0" iyz="0"
          izz="0.0"
      />
    </inertial>

    <collision name='wheel_collision'>
      <origin xyz="0 0 0" rpy=" 0 1.5705 1.5705"/> 
      <geometry>
        <cylinder length="0.05" radius="0.1"/>
      </geometry>
    </collision>

    <visual name='wheel_visual'>
      <origin xyz="0 0 0" rpy=" 0 1.5705 1.5705"/>
      <geometry>
        <cylinder length="0.05" radius="0.1"/>
      </geometry>
    </visual>
  </link>

  <link name='right_wheel'>
    <inertial>
      <mass value="5.0"/>
      <origin xyz="0.0 0 0" rpy=" 0 1.5705 1.5707"/>
      <inertia
          ixx="0.0" ixy="0" ixz="0"
          iyy="0.0" iyz="0"
          izz="0.0"
      />
    </inertial>

    <collision name='wheel_collision'>
      <origin xyz="0 0 0" rpy=" 0 1.5705 1.5705"/> 
      <geometry>
        <cylinder length="0.05" radius="0.1"/>
      </geometry>
    </collision>

    <visual name='wheel_visual'>
      <origin xyz="0 0 0" rpy=" 0 1.5705 1.5705"/>
      <geometry>
        <cylinder length="0.05" radius="0.1"/>
      </geometry>
    </visual>
  </link>


<!--> sensors___________________________________________________<!-->


  <link name='camera_depth_frame'></link>
  <link name="camera_compensation_frame"></link>
    

  <link name='camera'>
    <inertial>
      <mass value="0.1"/>
      <origin xyz="0.0 0 0" rpy=" 0 0 0"/>
      <inertia
          ixx="0" ixy="0" ixz="0"
          iyy="0" iyz="0"
          izz="0"
      />
    </inertial>

    <collision name='camera_collision'>
      <origin xyz="0 0 0" rpy=" 0 0 0"/> 
      <geometry>
        <box size="0.05 0.05 0.05"/>
      </geometry>
    </collision>

    <visual name='camera_visual'>
      <origin xyz="0 0 0" rpy=" 0 0 0"/>
      <geometry>
        <box size="0.05 0.05 0.05"/>
      </geometry>
    </visual>
  </link>

<!--
  <link name='hokuyo'>
    <inertial>
      <mass value="0.1"/>
      <origin xyz="0.0 0 0" rpy=" 0 0 0"/>
      <inertia
          ixx="1e-6" ixy="0" ixz="0"
          iyy="1e-6" iyz="0"
          izz="1e-6"
      />
    </inertial>

    <collision name='hokuyo_collision'>
      <origin xyz="0 0 0" rpy=" 0 0 0"/> 
      <geometry>
        <box size="0.05 0.05 0.05"/>
      </geometry>
    </collision>

    <visual name='hokuyo_visual'>
      <origin xyz="0 0 0" rpy=" 0 0 0"/>
      <geometry>
        <mesh filename="package://robot_slam/meshes/hokuyo.dae"/>
      </geometry>
    </visual>
  </link>
-->
<!--> joints_________________________________________________<!-->


<!--> wheel_joints___________________________________________<!-->
  <joint type="continuous" name="left_wheel_hinge">
    <origin xyz="0 0.15 0" rpy="0 0 0"/>
    <child link="left_wheel"/>
    <parent link="chassis"/>
    <axis xyz="0 1 0" rpy="0 0 0"/>
    <limit effort="10000" velocity="1000"/>
    <dynamics damping="1.0" friction="1.0"/>
  </joint>

  <joint type="continuous" name="right_wheel_hinge">
    <origin xyz="0 -0.15 0" rpy="0 0 0"/>
    <child link="right_wheel"/>
    <parent link="chassis"/>
    <axis xyz="0 1 0" rpy="0 0 0"/>
    <limit effort="10000" velocity="1000"/>
    <dynamics damping="1.0" friction="1.0"/>
  </joint>

<!--> sensors_joints_________________________________________<!-->
  <joint type="fixed" name="camera_joint">
    <origin xyz="0.2 0 0" rpy="0 0 0"/>
    <child link="camera"/>
    <parent link="chassis"/>
  </joint>

  <joint type="fixed" name="camera_depth_joint">
    <origin xyz="0.2 0 0" rpy="0 0 0"/>
    <child link="camera_depth_frame"/>
    <parent link="chassis"/>
  </joint>
  
  <joint name="camera_compensation_joint" type="fixed">
    <origin xyz="0 0 0" rpy="-1.5707 0 -1.5707" />
    <child link="camera_compensation_frame" />
    <parent link="camera" />
  </joint>-->

  
<!--
  <joint type="fixed" name="hokuyo_joint">
    <origin xyz="0.15 0 0.1" rpy="0 0 0"/>
    <child link="hokuyo"/>
    <parent link="chassis"/>
  </joint>

-->

</robot>
